# （二）Promise 的理解和使用

## 1. Promise 的理解

### 1.1 定义

MDN 上的定义：一个 `Promise` 对象代表一个在这个 `Promise` 被创建出来时不一定已知的值。它让您能够 **把异步操作最终的成功返回值或者失败原因和相应的处理程序关联起来**。 这样使得异步方法可以像同步方法那样返回值：**异步方法并不会立即返回最终的值，而是会返回一个 promise，以便在未来某个时候把值交给使用者**。

- 抽象表达：Promise 是 ES6 引入的异步编程的新解决方案。在 Promise 出现之前，只是单纯的使用回调函数。
- 具体表达：Promise 是一个构造函数，由 Promise 产生的对象用来封装一个异步操作，并且可以获取其成功/失败的最终结果。

### 1.2 Promise 的状态

一个 `Promise` 必然处于以下几种状态之一：
- 待定（`pending`）: 初始状态，既没有被兑现，也没有被拒绝。
- 成功（`fulfilled`）: 意味着操作成功完成。
- 失败（`rejected`）: 意味着操作失败。

一个 `Promise` 的状态只能由 `pending` 变为 `fulfilled`，或者变为 `rejected`，且只能改变一次。

链式调用：`Promise` 对象具有 `then` 和 `catch` 方法来处理下一步的操作。因为 `Promise.prototype.then` 和 `Promise.prototype.catch` 方法返回的是 `Promise`，所以它们可以被链式调用。

### 1.3 Promise 的基本流程

![Promise](https://cdn.jsdelivr.net/gh/Hacker-C/Picture-Bed@main/front-end/Promise.rtseidrtnm8.webp)

一个 `Promise` 对象刚被创建时的初始状态为 `pending`。接下来会执行异步操作，若异步操作成功，则执行 `resolve()` 函数，可将成功返回的数据通过 `resolve(data)` 返回。若异步操作失败，则执行 `reject()` 函数，将失败的信息返回。

无论成功还是失败，返回的都是 `Promise` 对象，具有 `then()` 和 `catch()` 方法。

返回的 `Promise` 使用 `then()` 调用：
```js
promise.then(successCallback, failureCallback);
```
其中，`successCallback` 是成功的回调函数，`failureCallback` 是失败的回调函数。一般格式为：
```js
promise.then(value=>{}, reason=>{})
```

### 1.4 Promise 的基本使用

构造函数 `Promise()`内部自动执行一个 **执行器函数**，也叫 `excutor`。这个执行器函数又接收两个参数，第一个为执行成功的回调函数（`resolve`），第二个为操作成功的回调函数（`reject`）。

需要注意，**excutor 执行器函数是同步回调函数**。  
例如有以下代码：
```js
new Promise(
  // 执行器函数开始
  (resolve, reject) => {
    console.log(1)
    // 异步操作
    setTimeout(() => {
      console.log(2)
    }, 0)
    console.log(3)
  }
)
console.log(4)
```
打印结果是：1、3、4、2

**基本使用流程**
```js
const promise = new Promise((resolve, reject) => {

  // 执行异步操作
  // 操作成功，可将数据传入
  resolve(data)
  // 操作失败，可将错误信息传入
  reject(err_msg)

})

// 处理返回结果
promise.then(
  // 操作成功的回调
  value => { },
  // 操作失败的回调
  reason => { }
)
```

具体例子如下：
```js
// 1. 创建 Promise 对象，此时为 pending 状态
const promise = new Promise((resolve, reject) => {
  // 2. 执行异步操作，这里是定时器函数
  setTimeout(() => {
    let time = Date.now()
    if (time % 2 === 1) {
      // 2.1 假定 time 为奇数时为操作成功，则执行 resolve
      resolve('成功的值：' + time)
    } else {
      // 2.1 假定 time 为偶时为操作失败，则执行 reject
      reject('失败的值：' + time)
    }
  }, 1000)
})

// 3. promise 能指定成功或失败的回调函数来获取成功的 value，或失败的 reason
promise.then(
  // 3.1 操作成功（resolve）的回调函数
  value => {
    console.log(value)
  },
  // 3.1 操作失败哦（reject）的回调函数
  reason => {
    console.log(reason)
  }
)
```

## 2. 为什么要使用 Promise

原因：
- 指定回调函数的方式更加灵活
- 支持链式调用，解决回调地狱问题

### 2.1 指定回调函数的方式更加灵活

- 在出现 Promise 以前，纯回调方式：在启动异步任务的同时，必须先指定好回调函数，否则会拿不到数据。
- Promise：启动异步任务 => 返回 Promise 对象 => 给 promise 绑定回调函数。甚至可以在异步任务结束后再指定回调函数，而这在单纯的回调方式中是不行的。

下面举例说明。

#### 2.1.1 MDN 上的例子

使用 MDN 上的例子：假设现在有一个名为 `createAudioFileAsync()` 的函数，它接收一些配置和两个回调函数，然后异步地生成音频文件。一个回调函数在文件成功创建时被调用，另一个则在出现异常时被调用。创建一个文件需要一些时间，因此是一个异步回调。

> 参考：https://developer.mozilla.org/zh-CN/docs/Web/JavaScript/Guide/Using_promises

为了方便说明，下面都是伪代码。

```js
// 成功的回调函数
function successCallback(result) {
  console.log("声音文件创建成功: " + result);
}
// 失败的回调函数
function failureCallback(error) {
  console.log("声音文件创建失败: " + error);
}
```

传统的纯回调方式，需要先指定好成功和失败的回调函数。也就是说，在文件创建的结果出来之前，回调函数必须先指定好，否则文件的结果无法处理。

```js
createAudioFileAsync(audioSettings, successCallback, failureCallback)
```

对于 `Promise`，无需考虑这方面。**在启动异步任务之前或者之后，都可以指定好回调函数。这样，异步任务指定回调函数的方式就更加灵活了**。

```js
const promise = createAudioFileAsync(audioSettings);
promise.then(successCallback, failureCallback);
```

#### 2.1.2 实际例子

上述说明比较抽象，下面来一个实际情况的例子。

假如现在有一个 ajax 请求，获取服务器的某用户的名字。从发出请求到获得结果需要花费一些时间，这里使用定时器模拟请求。

```js
function success(name) {
  console.log('成功：' + name)
}

function failure(msg) {
  console.log('失败：' + msg)
}
```

**传统纯回调方式**

```js
function ajax(success, failure) {
  setTimeout(() => {
    // 这里可以假设获取数据成功或失败
    success('peter')
  }, 1000)
}

// 在启动异步任务的同时，必须先指定好 success 和 failure
ajax(success, failure)
// 输出：peter
```

**Promise 方式**

```js
const promise = new Promise((resolve, reject) => {
  // 模拟 ajax 请求，1s后获取到数据
  setTimeout(() => {
    resolve('peter')
  }, 1000)
})
// 此时异步任务已启动，不必先指定回调
```

可以在异步任务启动之后，在指定好回调函数

```js
promise.then(value => {
  success(value)
}, reason => {
  failure(reason)
})
// 输出：peter
```

甚至可以在异步任务完成后指定。请求在 1s 完成，而指定回调队列在 2s 完成。

```js
setTimeout(() => {
  promise.then(value => {
    success(value)
  }, reason => {
    failure(reason)
  })
}, 2000)
// 输出：peter
```

### 2.2 支持链式调用，解决回调地狱问题

#### 2.2.1 回调地狱

回调地狱：回调函数嵌套调用，**外部回调函数异步执行的结果是嵌套的回调函数执行的条件**。  
回调地狱的缺点：**不便于阅读，不便于异常处理**。

开发中经常会遇到多重异步操作，就会出现下面的写法（伪代码）：
```js
doSomething(function(result) {
  doSomethingElse(result, function(newResult) {
    doThirdThing(newResult, function(finalResult) {
      console.log('Got the final result: ' + finalResult);
    }, failureCallback);
  }, failureCallback);
}, failureCallback);
```

例如，现在要获取一个用户所有的商品数据，首先要根据用户名获取用户ID，然后根据ID获取订单信息，根据订单信息获取商品信息。一共要发起三次请求，前面的请求结果是后面请求的条件。

#### 2.2.2 链式调用，解决回调地狱

一个 `Promise` 对象具有 `then` 和 `catch` 方法，而 `then` 和 `catch` 的返回结果依然是一个 `Promise` 对象，因此可以使用 `.` 符号进行链式调用。

对于上述伪代码，使用 `Promise`的形式改写如下：

```js
// 把回调绑定到返回的 Promise 上，形成一个 Promise 链
doSomething().then(function(result) {
  return doSomethingElse(result);
})
.then(function(newResult) {
  return doThirdThing(newResult);
})
.then(function(finalResult) {
  console.log('Got the final result: ' + finalResult);
})
.catch(failureCallback);
```

链式调用格式：
```js
const p = new Promise(resolve=>{}, reject=>{});
p.then(value=>{}, reason=>{})
.then(value=>{}, reason=>{})
.then(value=>{}, reason=>{})
...
```

### 2.3 终极方案：使用 async/await

`Promise` 链式调用已经解决了回调地狱函数层层嵌套的问题了，还需要解决什么问题么？没错，我们还要砍掉 `Promise` 的回调函数，**回调函数太多，代码写的很长**。

`async/await` 是 ES8 出的一个更加优雅的异步编程解决方案，它可以让异步操作代码变得像同步代码一样，看起来非常优雅而直观。

上述例子，使用 `async/await` 改写的形式：
```js
async function request() {
  try {
    const result = await doSomething()
    const newResult = await doSomethingElse(result)
    const finalResult = await doThirdThing(newResult)
    console.log('Got the final result: ' + finalResult);
  } catch (error) {
    failureCallback(error)
  }
}
```

这里提一下，后面会详细讲解。